2022-02-24 15:51:14,458 INFO    Thread-74 :534558 [wandb_setup.py:_flush():75] Loading settings from /home/sandip/.config/wandb/settings
2022-02-24 15:51:14,458 INFO    Thread-74 :534558 [wandb_setup.py:_flush():75] Loading settings from wandb/settings
2022-02-24 15:51:14,458 INFO    Thread-74 :534558 [wandb_setup.py:_flush():75] Loading settings from environment variables: {'entity': 'cookie303', 'project': 'Assignment1', 'root_dir': '/home/sandip/Desktop/DL/Assignment 1', 'run_id': 'pp3o9js9', 'sweep_param_path': '/home/sandip/Desktop/DL/Assignment 1/wandb/sweep-o42cpjd4/config-pp3o9js9.yaml', 'sweep_id': 'o42cpjd4'}
2022-02-24 15:51:14,458 INFO    Thread-74 :534558 [wandb_setup.py:_flush():75] Inferring run settings from compute environment: {'program': '<python with no main file>'}
2022-02-24 15:51:14,458 INFO    Thread-74 :534558 [wandb_init.py:_log_setup():386] Logging user logs to /home/sandip/Desktop/DL/Assignment 1/wandb/run-20220224_155114-pp3o9js9/logs/debug.log
2022-02-24 15:51:14,458 INFO    Thread-74 :534558 [wandb_init.py:_log_setup():387] Logging internal logs to /home/sandip/Desktop/DL/Assignment 1/wandb/run-20220224_155114-pp3o9js9/logs/debug-internal.log
2022-02-24 15:51:14,458 INFO    Thread-74 :534558 [wandb_init.py:init():420] calling init triggers
2022-02-24 15:51:14,459 INFO    Thread-74 :534558 [wandb_init.py:init():425] wandb.init called with sweep_config: {'activation': 'Sigmoid', 'batch_size': 64, 'epochs': 10, 'initializer': 'he', 'learning_rate': 0.001, 'num_hidden_neurons': 32, 'num_layers': 3, 'optimizer': 'Adam', 'weight_decay': 0}
config: {'epochs': 5, 'num_hidden_layers': 3, 'num_hidden_neurons': 32, 'weight_decay': 0, 'learning_rate': 0.001, 'optimizer': 'SGD', 'batch_size': 16, 'activation': 'Tanh', 'initializer': 'xavier', 'loss': 'CategoricalCrossEntropy'}
2022-02-24 15:51:14,459 INFO    Thread-74 :534558 [wandb_init.py:init():471] starting backend
2022-02-24 15:51:14,459 INFO    Thread-74 :534558 [backend.py:_multiprocessing_setup():99] multiprocessing start_methods=fork,spawn,forkserver, using: spawn
2022-02-24 15:51:14,460 INFO    Thread-74 :534558 [backend.py:ensure_launched():219] starting backend process...
2022-02-24 15:51:14,466 INFO    Thread-74 :534558 [backend.py:ensure_launched():224] started backend process with pid: 536242
2022-02-24 15:51:14,467 INFO    Thread-74 :534558 [wandb_init.py:init():480] backend started and connected
2022-02-24 15:51:14,479 INFO    Thread-74 :534558 [wandb_run.py:_config_callback():966] config_cb None None {'activation': 'Sigmoid', 'batch_size': 64, 'epochs': 10, 'initializer': 'he', 'learning_rate': 0.001, 'num_hidden_neurons': 32, 'num_layers': 3, 'optimizer': 'Adam', 'weight_decay': 0}
2022-02-24 15:51:14,482 INFO    Thread-74 :534558 [wandb_run.py:_label_probe_notebook():921] probe notebook
2022-02-24 15:51:14,483 INFO    Thread-74 :534558 [wandb_init.py:init():550] updated telemetry
2022-02-24 15:51:14,501 INFO    Thread-74 :534558 [wandb_init.py:init():581] communicating current version
2022-02-24 15:51:15,117 INFO    Thread-74 :534558 [wandb_init.py:init():586] got version response 
2022-02-24 15:51:15,117 INFO    Thread-74 :534558 [wandb_init.py:init():596] communicating run to backend with 30 second timeout
2022-02-24 15:51:15,416 INFO    Thread-74 :534558 [wandb_init.py:init():624] starting run threads in backend
2022-02-24 15:51:20,126 INFO    Thread-74 :534558 [wandb_run.py:_console_start():1827] atexit reg
2022-02-24 15:51:20,126 INFO    Thread-74 :534558 [wandb_run.py:_redirect():1701] redirect: SettingsConsole.WRAP
2022-02-24 15:51:20,127 INFO    Thread-74 :534558 [wandb_run.py:_redirect():1738] Wrapping output streams.
2022-02-24 15:51:20,127 INFO    Thread-74 :534558 [wandb_run.py:_redirect():1762] Redirects installed.
2022-02-24 15:51:20,127 INFO    Thread-74 :534558 [wandb_init.py:init():651] run started, returning control to user process
2022-02-24 15:51:20,129 INFO    Thread-74 :534558 [wandb_run.py:finish():1468] finishing run cookie303/Assignment1/pp3o9js9
2022-02-24 15:51:20,129 INFO    Thread-74 :534558 [wandb_run.py:_atexit_cleanup():1797] got exitcode: 1
2022-02-24 15:51:20,131 INFO    Thread-74 :534558 [wandb_run.py:_restore():1769] restore
2022-02-24 15:51:21,143 INFO    Thread-74 :534558 [wandb_run.py:_wait_for_finish():1929] got exit ret: file_counts {
  wandb_count: 1
}
pusher_stats {
  uploaded_bytes: 753
  total_bytes: 753
}

2022-02-24 15:51:21,502 INFO    Thread-74 :534558 [wandb_run.py:_wait_for_finish():1929] got exit ret: file_counts {
  wandb_count: 1
}
pusher_stats {
  uploaded_bytes: 753
  total_bytes: 753
}

2022-02-24 15:51:22,432 INFO    Thread-74 :534558 [wandb_run.py:_restore():1769] restore
2022-02-24 15:51:25,540 ERROR   Thread-74 :534558 [wandb_run.py:_atexit_cleanup():1815] Problem finishing run
Traceback (most recent call last):
  File "/home/sandip/anaconda3/lib/python3.9/site-packages/wandb/agents/pyagent.py", line 302, in _run_job
    self._function()
  File "/tmp/ipykernel_534558/1802991598.py", line 45, in sweep
    model.set(
TypeError: set() got an unexpected keyword argument 'accuracy'

During handling of the above exception, another exception occurred:

Traceback (most recent call last):
  File "/home/sandip/anaconda3/lib/python3.9/site-packages/wandb/sdk/wandb_run.py", line 1805, in _atexit_cleanup
    self._on_finish()
  File "/home/sandip/anaconda3/lib/python3.9/site-packages/wandb/sdk/wandb_run.py", line 1988, in _on_finish
    self._poll_exit_response = self._wait_for_finish()
  File "/home/sandip/anaconda3/lib/python3.9/site-packages/wandb/sdk/wandb_run.py", line 1928, in _wait_for_finish
    poll_exit_resp = self._backend.interface.communicate_poll_exit()
  File "/home/sandip/anaconda3/lib/python3.9/site-packages/wandb/sdk/interface/interface.py", line 586, in communicate_poll_exit
    resp = self._communicate_poll_exit(poll_exit)
  File "/home/sandip/anaconda3/lib/python3.9/site-packages/wandb/sdk/interface/interface_shared.py", line 402, in _communicate_poll_exit
    result = self._communicate(rec)
  File "/home/sandip/anaconda3/lib/python3.9/site-packages/wandb/sdk/interface/interface_shared.py", line 213, in _communicate
    return self._communicate_async(rec, local=local).get(timeout=timeout)
  File "/home/sandip/anaconda3/lib/python3.9/site-packages/wandb/sdk/interface/router.py", line 37, in get
    is_set = self._object_ready.wait(timeout)
  File "/home/sandip/anaconda3/lib/python3.9/threading.py", line 574, in wait
    signaled = self._cond.wait(timeout)
  File "/home/sandip/anaconda3/lib/python3.9/threading.py", line 316, in wait
    gotit = waiter.acquire(True, timeout)
Exception
